Workbook
Name Slicer_Department: #N/A
Name Slicer_Role: #N/A
Name Slicer_Work_Mode: #N/A

Sheet Raw
A1: Emp_ID | B1: Emp_Name | C1: Age | D1: Gender | E1: City | F1: Department | G1: Role | H1: Currency | I1: Monthly_Salary | J1: Num_Month | K1: Exp_Years | L1: Performance_Rating | M1: Bonus | N1: Attendance_% | O1: Leaves_Taken | P1: Projects_Handled | Q1: Promotion_Status | R1: Work_Mode | S1: Shift | T1: Overtime_Hours | U1: Training_Hours | V1: Salary_Band
A2: ZOM1328 | B2: Employee_328_India | C2: 44 | D2: F | E2: Bangalore | F2: Customer Support | G2: Director | H2: INR | I2: 99000 | J2: 12 | K2: 11 | L2: 4 | M2: 59000 | N2: 90 | O2: 15 | P2: 3 | R2: Hybrid | S2: Day | V2: Medium
A3: ZOM1042 | B3: Employee_42_India | C3: 24 | D3: F | E3: Bangalore | F3: Logistics | G3: Lead Analyst | H3: INR | I3: 70500 | J3: 12 | K3: 7 | L3: 4 | M3: 10871 | N3: 80 | O3: 5 | P3: 5 | R3: Hybrid | S3: Day | T3: 5 | V3: Medium
A4: ZOM1377 | B4: Employee_377_India | C4: 25 | E4: Pune | F4: Operations | G4: Senior Analyst | H4: INR | I4: 36000 | J4: 12 | K4: 3 | L4: 3 | M4: 10000 | N4: 90 | O4: 5 | P4: 1 | Q4: No | R4: Hybrid | S4: Day | T4: 10 | U4: 20 | V4: Medium
A5: ZOM1076 | B5: Employee_76_India | C5: 27 | D5: M | E5: Gurugram | F5: Logistics | G5: Senior Analyst | H5: INR | I5: 36000 | J5: 12 | K5: 3 | L5: 3 | M5: 8000 | N5: 80 | O5: 5 | P5: 3 | S5: Day | T5: 10 | U5: 30 | V5: Medium
A6: ZOM1103 | B6: Employee_103_India | C6: 27 | D6: M | E6: Delhi | F6: Logistics | G6: Senior Analyst | H6: INR | I6: 49000 | J6: 12 | K6: -4 | L6: 2 | M6: 23300 | N6: 95 | O6: 5 | P6: 3 | Q6: Yes | R6: Hybrid | S6: Day | T6: 5 | U6: 30 | V6: Low
A7: ZOM1014 | B7: Employee_14_India | C7: 27 | E7: Delhi | F7: Analytics | G7: Senior Analyst | H7: INR | I7: 51000 | J7: 12 | K7: 4 | L7: 3 | M7: 10000 | N7: 88 | O7: 5 | P7: 5 | R7: Hybrid | S7: Day | U7: 12 | V7: Medium
A8: ZOM1333 | B8: Employee_333_India | C8: 26 | D8: F | F8: Operations | G8: Senior Analyst | H8: INR | I8: 42000 | J8: 12 | K8: 3 | L8: 1 | M8: 23400 | N8: 95 | O8: 15 | P8: 5 | Q8: No | R8: Hybrid | S8: Day | T8: 10 | U8: 20 | V8: Low
A9: ZOM1625 | B9: Employee_25_India | C9: 25 | D9: Female | E9: Chennai | F9: Operations | G9: Senior Analyst | H9: USD | I9: 36000 | J9: 12 | K9: 3 | L9: 4 | M9: 15000 | N9: 80 | O9: 7 | P9: 5 | R9: Remote | S9: Day | U9: 20 | V9: High
A10: ZOM1005 | B10: Employee_5_India | C10: 26 | E10: Hyderabad | F10: Operations | G10: Senior Analyst | H10: INR | I10: 42333 | J10: 12 | K10: 3 | L10: 4 | M10: 15000 | N10: 85 | O10: 10 | P10: 3 | S10: Day | T10: 5 | U10: 30 | V10: Medium
A11: ZOM1570 | B11: Employee_570_India | C11: 26 | D11: F | E11: Mumbai | F11: Logistics | G11: Senior Analyst | H11: INR | I11: 48000 | J11: 12 | K11: 4 | L11: 1 | M11: 24000 | N11: 88 | O11: 7 | P11: 1 | Q11: No | R11: Office | S11: Day | U11: 2 | V11: Low
A12: ZOM1142 | B12: Employee_142_India | C12: 26 | D12: F | E12: Kolkata | F12: Customer Support | G12: Senior Analyst | H12: INR | I12: 48000 | J12: 13 | K12: 4 | L12: 4 | M12: 15000 | N12: 90 | O12: 10 | P12: 1 | Q12: Yes | R12: Hybrid | S12: Day | T12: 5 | U12: 10 | V12: Medium
A13: ZOM1507 | B13: Employee_507_India | C13: 26 | D13: Female | E13: Noida | F13: Customer Support | G13: Senior Analyst | H13: INR | I13: 31000 | J13: 12 | K13: 2 | L13: 5 | M13: 19000 | N13: 85 | O13: 7 | P13: Five | R13: Hybrid | S13: Night | T13: 20 | V13: High
A14: ZOM1068 | B14: Employee_68_India | C14: 27 | E14: Indore | F14: Operations | G14: Senior Analyst | H14: INR | I14: 35000 | J14: 12 | K14: 3 | L14: 1 | N14: 90 | O14: 5 | P14: 3 | Q14: No | R14: Hybrid | S14: Night | U14: 20 | V14: Low
A15: ZOM1372 | B15: Employee_372_India | C15: 25 | D15: F | E15: Kolkata | F15: HR | G15: Senior Analyst | H15: INR | I15: 38000 | J15: 12 | K15: 3 | L15: 5 | M15: 24000 | N15: 90 | O15: 15 | P15: 5 | R15: Hybrid | S15: Day | U15: 20 | V15: High
A16: ZOM1451 | B16: Employee_451_India | C16: 26 | E16: Gurugram | F16: Analytics | G16: Senior Analyst | H16: INR | I16: 48000 | J16: 12 | K16: 4 | L16: 4 | M16: 15000 | N16: 90 | O16: 15 | P16: 1 | Q16: Yes | R16: Hybrid | S16: Day | T16: 20 | U16: 30 | V16: High
A17: ZOM1206 | B17: Employee_206_India | C17: 45 | D17: Female | E17: Bangalore | F17: Analytics | G17: Director | H17: USD | I17: 110000 | J17: 12 | K17: 10 | L17: 2 | N17: 88 | O17: 7 | P17: 5 | Q17: Yes | R17: Office | S17: Night | U17: 12 | V17: Low
A18: ZOM1318 | B18: Employee_318_India | C18: 45 | D18: F | E18: Chennai | F18: Finance | G18: Director | H18: INR | I18: 120000 | J18: 12 | K18: 12 | L18: 2 | N18: 80 | O18: 5 | P18: 3 | R18: Hybrid | S18: Day | U18: 20 | V18: Low
A19: ZOM1212 | B19: Employee_212_India | C19: 37 | D19: F | E19: Gurugram | F19: Analytics | G19: Senior Manager | H19: INR | I19: 90000 | J19: 12 | K19: 12 | L19: 4 | M19: 47000 | N19: 85 | O19: 7 | P19: 3 | Q19: Yes | R19: Hybrid | S19: Night | T19: 5 | V19: High
A20: ZOM1255 | B20: Employee_255_India | C20: 41 | D20: F | E20: Indore | F20: Finance | G20: Director | H20: INR | I20: 123000 | J20: 12 | K20: 13 | L20: 3 | M20: 54000 | N20: 95 | O20: 15 | P20: 2 | Q20: Yes | R20: Office | S20: Day | T20: 10 | U20: 11 | V20: Medium
A21: ZOM1390 | B21: Employee_390_India | C21: 26 | D21: Female | F21: Operations | G21: Senior Analyst | H21: INR | I21: 48000 | J21: 12 | K21: 4 | L21: 1 | N21: 88 | O21: 15 | P21: 2 | R21: Hybrid | S21: Day | T21: 20 | U21: 10 | V21: Low
A22: ZOM1234 | B22: Employee_234_India | C22: 26 | D22: Female | E22: Hyderabad | F22: Analytics | G22: Senior Analyst | H22: INR | I22: 32000 | J22: 15 | K22: 2 | L22: 4 | M22: 15000 | N22: 88 | O22: 10 | P22: 5 | R22: Office | S22: Night | U22: 20 | V22: Medium
A23: ZOM1385 | B23: Employee_385_India | C23: 34 | D23: Male | E23: Hyderabad | F23: Logistics | G23: Manager | H23: INR | I23: 79000 | J23: 12 | K23: 6 | L23: 5 | M23: 32000 | N23: 85 | O23: 10 | P23: Three | Q23: Yes | R23: Hybrid | S23: Night | T23: 10 | U23: 30 | V23: High
A24: ZOM1058 | B24: Employee_58_India | C24: 44 | D24: F | E24: Kolkata | F24: Customer Support | G24: Director | H24: INR | I24: 120000 | J24: 12 | K24: 10 | L24: 4 | M24: 54000 | N24: 85 | O24: 7 | P24: 3 | Q24: No | R24: Hybrid | S24: Night | V24: High
A25: ZOM1073 | B25: Employee_73_India | C25: 27 | D25: F | E25: Delhi | F25: Logistics | G25: Senior Analyst | H25: INR | I25: 38000 | J25: 12 | K25: 3 | L25: 1 | N25: 88 | O25: 15 | P25: 2 | Q25: Yes | R25: Office | S25: Day | T25: 20 | U25: 30 | V25: Low
A26: ZOM1360 | B26: Employee_360_India | C26: 27 | D26: Male | E26: Pune | F26: Analytics | G26: Lead Analyst | H26: INR | I26: 78000 | J26: 12 | K26: 6 | L26: 3 | M26: 11000 | N26: 88 | O26: 15 | P26: 1 | R26: Office | S26: Night | T26: 10 | V26: Medium
A27: ZOM1051 | B27: Employee_51_India | C27: 27 | D27: F | E27: Kolkata | F27: Customer Support | G27: Senior Analyst | H27: INR | I27: 38000 | J27: 12 | K27: 3 | L27: 1 | N27: 80 | O27: 10 | P27: 5 | Q27: No | R27: Hybrid | S27: Day | T27: 10 | U27: 13 | V27: Low
A28: ZOM1459 | B28: Employee_459_India | C28: 45 | E28: Indore | F28: Customer Support | G28: Director | H28: INR | I28: 110000 | J28: 12 | K28: 10 | L28: 1 | N28: 90 | O28: 10 | P28: 1 | Q28: No | R28: Office | S28: Night | U28: 30 | V28: Low
A29: ZOM1278 | B29: Employee_278_India | C29: 38 | D29: M | E29: Kolkata | F29: Finance | G29: Senior Manager | H29: USD | I29: 91600 | J29: 12 | K29: 12 | L29: 4 | M29: 43000 | N29: 90 | O29: 5 | P29: 5 | Q29: Yes | R29: Office | S29: Night | T29: 20 | U29: 20 | V29: Medium
A30: ZOM1572 | B30: Employee_572_India | C30: 26 | D30: F | E30: Noida | F30: Logistics | G30: Senior Analyst | H30: INR | I30: 42500 | J30: 12 | K30: 3 | L30: 2 | N30: 80 | O30: 10 | P30: 1 | Q30: Yes | R30: Office | S30: Day | T30: 5 | V30: Low
A31: ZOM1529 | B31: Employee_529_India | C31: 36 | D31: Female | E31: Pune | F31: Finance | G31: Senior Manager | H31: INR | I31: 91700 | J31: 12 | K31: 12 | L31: 2 | N31: 88 | O31: 7 | P31: 5 | Q31: No | R31: Hybrid | S31: Night | T31: 20 | U31: 30 | V31: Low
A32: ZOM1609 | B32: Employee_9_Foreign | C32: 25 | D32: Male | F32: Operations | G32: Senior Analyst | H32: USD | I32: 31000 | J32: 12 | K32: 2 | L32: 2 | N32: 80 | O32: 10 | P32: 3 | Q32: Yes | R32: Remote | S32: Day | U32: 10 | V32: Low
A33: ZOM1339 | B33: Employee_339_India | C33: 25 | D33: Male | E33: Delhi | F33: Analytics | G33: Senior Analyst | H33: INR | I33: 33000 | J33: 12 | K33: 2 | L33: 1 | N33: 85 | O33: 5 | P33: 1 | R33: Office | S33: Night | T33: 20 | V33: Low
A34: ZOM1597 | B34: Employee_597_India | C34: 25 | D34: F | E34: Hyderabad | F34: Finance | G34: Senior Analyst | H34: INR | I34: 45000 | J34: 12 | K34: 4 | L34: 1 | N34: 95 | O34: 15 | P34: 1 | R34: Hybrid | S34: Day | T34: 10 | V34: Low
A35: ZOM1188 | B35: Employee_188_India | C35: 27 | D35: M | E35: Noida | F35: Analytics | G35: Senior Analyst | H35: INR | I35: 43000 | J35: 12 | K35: 3 | L35: 1 | N35: 88 | O35: 15 | P35: 1 | Q35: No | R35: Hybrid | S35: Night | T35: 5 | U35: 30 | V35: Low
A36: ZOM1655 | B36: Employee_55_Foreign | C36: 32 | D36: Male | E36: Bangalore | F36: Logistics | G36: Manager | H36: INR | I36: 80000 | J36: 12 | K36: 8 | L36: 4 | N36: 90 | O36: 5 | P36: 7 | Q36: Yes | R36: Office | S36: Day | T36: 20 | U36: 30 | V36: Medium
A37: ZOM1098 | B37: Employee_98_India | C37: 29 | E37: Kolkata | F37: Logistics | G37: Lead Analyst | H37: INR | I37: 78000 | J37: 12 | K37: 5 | L37: 1 | N37: 85 | O37: 10 | P37: 1 | R37: Hybrid | S37: Night | T37: 20 | U37: 2 | V37: Low
A38: ZOM1040 | B38: Employee_40_India | C38: 38 | E38: Delhi | F38: Logistics | G38: Director | H38: INR | I38: 110000 | J38: 12 | K38: 11 | L38: 5 | M38: 65000 | N38: 95 | O38: 10 | P38: 5 | Q38: Yes | R38: Hybrid | S38: Night | U38: 22 | V38: High
A39: ZOM1273 | B39: Employee_273_India | C39: 38 | D39: F | E39: Mumbai | F39: HR | G39: Director | H39: INR | I39: 99000 | J39: 12 | K39: 13 | L39: 4 | M39: 58000 | N39: 90 | O39: 7 | P39: 2 | Q39: Yes | R39: Hybrid | S39: Night | U39: 30 | V39: Medium
A40: ZOM1045 | B40: Employee_45_India | C40: 27 | D40: Female | E40: Chennai | F40: Logistics | G40: Lead Analyst | H40: INR | I40: 79000 | J40: 12 | K40: 6 | L40: 4 | M40: 10871 | N40: 87 | O40: 15 | P40: Two | Q40: Yes | R40: Office | S40: Night | T40: 10 | U40: 20 | V40: High
...

Sheet Raw_2
A1: Department | B1: Shift | C1: Training_Hours
A2: Customer Support | B2: Day | C2: 12
A3: Logistics | B3: Night | C3: 13
A4: Operations | B4: Day | C4: 14
A5: Analytics | B5: Day | C5: 25
A6: HR | B6: Day | C6: 10
A7: Finance | B7: Night | C7: 20

Sheet Working
A1: Emp_ID | B1: Emp_Name | C1: Age | D1: Gender | E1: Gender_Final | F1: City | G1: Department | H1: Role | I1: Currency | J1: Currency_Final | K1: Monthly_Salary | L1: Num_Month | M1: Num_Month_Final | N1: Annual_Salary | O1: Exp_Years | P1: Exp_Years_Final | Q1: Performance_Rating | R1: Bonus | S1: Bonus Final | T1: Attendance_% | U1: Leaves_Taken | V1: Projects_Handled | W1: Promotion_Status | X1: Work_Mode | Y1: Work_Mode_Final | Z1: Overtime_Hours | AA1: Overtime_Cost | AB1: Salary_Band | AC1: Emp_Dup_Check | AD1: Row_Concat | AE1: Row_Status | AF1: Row_Number | AG1: Exclusion | AH1: Shift | AI1: Training_Hours
A2: ZOM1328 | B2: Employee_328_India | C2: 44 | D2: F | E2: =IF(OR(Table2[[#This Row],[Gender]]="Male",Table2[[#This Row],[Gender]]="M"),"M", IF(OR(Table2[[#This Row],[Gender]]="Female",Table2[[#This Row],[Gender]]="F"),"F","")) -> F | F2: Bangalore | G2: Customer Support | H2: Director | I2: INR | J2: =IF(ISNUMBER(SEARCH("India",Table2[[#This Row],[Emp_Name]])),"INR", IF(ISNUMBER(SEARCH("Foreign",Table2[[#This Row],[Emp_Name]])),Table2[[#This Row],[Currency]],Table2[[#This Row],[Currency]])) -> INR | K2: 99000 | L2: 12 | M2: =IF(Table2[[#This Row],[Num_Month]]<>12,12,Table2[[#This Row],[Num_Month]]) -> 12 | N2: =IF(Table2[[#This Row],[Monthly_Salary]]="","",Table2[[#This Row],[Monthly_Salary]]*Table2[[#This Row],[Num_Month_Final]]) -> 1188000 | O2: 11 | P2: =IF(Table2[[#This Row],[Exp_Years]]<0,ABS(Table2[[#This Row],[Exp_Years]]),Table2[[#This Row],[Exp_Years]]) -> 11 | Q2: 4 | R2: 59000 | S2: =IF(Table2[[#This Row],[Performance_Rating]]>=3,Table2[[#This Row],[Monthly_Salary]]*0.3,"") -> 29700 | T2: 90 | U2: 15 | V2: 3 | X2: Hybrid | Y2: =IF(Table2[[#This Row],[Work_Mode]]<>"",Table2[[#This Row],[Work_Mode]], IF(ISNUMBER(SEARCH("India",Table2[[#This Row],[Emp_Name]])),"Office", IF(ISNUMBER(SEARCH("Foreign",Table2[[#This Row],[Emp_Name]])),"Remote",""))) -> Hybrid | AA2: =IF(OR(Table2[[#This Row],[Role]]="Intern",Table2[[#This Row],[Role]]="Administrative Assistant",Table2[[#This Row],[Role]]="Analyst"), Table2[[#This Row],[Overtime_Hours]]*250, IF(OR(Table2[[#This Row],[Role]]="Senior Analyst",Table2[[#This Row],[Role]]="Specialist",Table2[[#This Row],[Role]]="Lead Analyst"), Table2[[#This Row],[Overtime_Hours]]*300, IF(OR(Table2[[#This Row],[Role]]="Manager",Table2[[#This Row],[Role]]="Senior Manager"), Table2[[#This Row],[Overtime_Hours]]*350, ""))) | AB2: Medium | AC2: =IF(COUNTIF(Table2[Emp_ID],Table2[[#This Row],[Emp_ID]])>1,"Duplicate","Unique") -> Unique | AD2: =_xlfn.TEXTJOIN("|",TRUE,Table2[[#This Row],[Emp_ID]:[Salary_Band]]) -> ZOM1328|Employee_328_India|44|F|F|Bangalore|Customer Support|Director|INR|INR|99000|12|12|1188000|11|11|4|59000|29700|90|15|3|Hybrid|Hybrid|Medium | AE2: =IF(COUNTIFS(Table2[Emp_ID],Table2[[#This Row],[Emp_ID]],Table2[Row_Concat],Table2[[#This Row],[Row_Concat]])>1,"Exact Duplicate", IF(COUNTIF(Table2[Emp_ID],Table2[[#This Row],[Emp_ID]])>1,"Mismatch","Unique")) -> Unique | AF2: =ROW() -> 2 | AG2: =IF(Table2[[#This Row],[Monthly_Salary]]="","Exclude", IF(Table2[[#This Row],[Row_Status]]="Mismatch","Exclude", IF(AND(Table2[[#This Row],[Row_Status]]="Exact Duplicate", COUNTIFS(Table2[Emp_ID],Table2[[#This Row],[Emp_ID]],Table2[Row_Concat],Table2[[#This Row],[Row_Concat]], Table2[Row_Number],"<"&Table2[[#This Row],[Row_Number]])>=1),"Delete",""))) | AH2: =VLOOKUP(Table2[[#This Row],[Department]],Raw_2!A:B,2,0) -> Day | AI2: =VLOOKUP(Table2[[#This Row],[Department]],Raw_2!A:C,3,0) -> 12
A3: ZOM1042 | B3: Employee_42_India | C3: 24 | D3: F | E3: =IF(OR(Table2[[#This Row],[Gender]]="Male",Table2[[#This Row],[Gender]]="M"),"M", IF(OR(Table2[[#This Row],[Gender]]="Female",Table2[[#This Row],[Gender]]="F"),"F","")) -> F | F3: Bangalore | G3: Logistics | H3: Lead Analyst | I3: INR | J3: =IF(ISNUMBER(SEARCH("India",Table2[[#This Row],[Emp_Name]])),"INR", IF(ISNUMBER(SEARCH("Foreign",Table2[[#This Row],[Emp_Name]])),Table2[[#This Row],[Currency]],Table2[[#This Row],[Currency]])) -> INR | K3: 70500 | L3: 12 | M3: =IF(Table2[[#This Row],[Num_Month]]<>12,12,Table2[[#This Row],[Num_Month]]) -> 12 | N3: =IF(Table2[[#This Row],[Monthly_Salary]]="","",Table2[[#This Row],[Monthly_Salary]]*Table2[[#This Row],[Num_Month_Final]]) -> 846000 | O3: 7 | P3: =IF(Table2[[#This Row],[Exp_Years]]<0,ABS(Table2[[#This Row],[Exp_Years]]),Table2[[#This Row],[Exp_Years]]) -> 7 | Q3: 4 | R3: 10871 | S3: =IF(Table2[[#This Row],[Performance_Rating]]>=3,Table2[[#This Row],[Monthly_Salary]]*0.3,"") -> 21150 | T3: 80 | U3: 5 | V3: 5 | X3: Hybrid | Y3: =IF(Table2[[#This Row],[Work_Mode]]<>"",Table2[[#This Row],[Work_Mode]], IF(ISNUMBER(SEARCH("India",Table2[[#This Row],[Emp_Name]])),"Office", IF(ISNUMBER(SEARCH("Foreign",Table2[[#This Row],[Emp_Name]])),"Remote",""))) -> Hybrid | Z3: 5 | AA3: =IF(OR(Table2[[#This Row],[Role]]="Intern",Table2[[#This Row],[Role]]="Administrative Assistant",Table2[[#This Row],[Role]]="Analyst"), Table2[[#This Row],[Overtime_Hours]]*250, IF(OR(Table2[[#This Row],[Role]]="Senior Analyst",Table2[[#This Row],[Role]]="Specialist",Table2[[#This Row],[Role]]="Lead Analyst"), Table2[[#This Row],[Overtime_Hours]]*300, IF(OR(Table2[[#This Row],[Role]]="Manager",Table2[[#This Row],[Role]]="Senior Manager"), Table2[[#This Row],[Overtime_Hours]]*350, ""))) -> 1500 | AB3: Medium | AC3: =IF(COUNTIF(Table2[Emp_ID],Table2[[#This Row],[Emp_ID]])>1,"Duplicate","Unique") -> Unique | AD3: =_xlfn.TEXTJOIN("|",TRUE,Table2[[#This Row],[Emp_ID]:[Salary_Band]]) -> ZOM1042|Employee_42_India|24|F|F|Bangalore|Logistics|Lead Analyst|INR|INR|70500|12|12|846000|7|7|4|10871|21150|80|5|5|Hybrid|Hybrid|5|1500|Medium | AE3: =IF(COUNTIFS(Table2[Emp_ID],Table2[[#This Row],[Emp_ID]],Table2[Row_Concat],Table2[[#This Row],[Row_Concat]])>1,"Exact Duplicate", IF(COUNTIF(Table2[Emp_ID],Table2[[#This Row],[Emp_ID]])>1,"Mismatch","Unique")) -> Unique | AF3: =ROW() -> 3 | AG3: =IF(Table2[[#This Row],[Monthly_Salary]]="","Exclude", IF(Table2[[#This Row],[Row_Status]]="Mismatch","Exclude", IF(AND(Table2[[#This Row],[Row_Status]]="Exact Duplicate", COUNTIFS(Table2[Emp_ID],Table2[[#This Row],[Emp_ID]],Table2[Row_Concat],Table2[[#This Row],[Row_Concat]], Table2[Row_Number],"<"&Table2[[#This Row],[Row_Number]])>=1),"Delete",""))) | AH3: =VLOOKUP(Table2[[#This Row],[Department]],Raw_2!A:B,2,0) -> Night | AI3: =VLOOKUP(Table2[[#This Row],[Department]],Raw_2!A:C,3,0) -> 13
A4: ZOM1377 | B4: Employee_377_India | C4: 25 | E4: =IF(OR(Table2[[#This Row],[Gender]]="Male",Table2[[#This Row],[Gender]]="M"),"M", IF(OR(Table2[[#This Row],[Gender]]="Female",Table2[[#This Row],[Gender]]="F"),"F","")) | F4: Pune | G4: Operations | H4: Senior Analyst | I4: INR | J4: =IF(ISNUMBER(SEARCH("India",Table2[[#This Row],[Emp_Name]])),"INR", IF(ISNUMBER(SEARCH("Foreign",Table2[[#This Row],[Emp_Name]])),Table2[[#This Row],[Currency]],Table2[[#This Row],[Currency]])) -> INR | K4: 36000 | L4: 12 | M4: =IF(Table2[[#This Row],[Num_Month]]<>12,12,Table2[[#This Row],[Num_Month]]) -> 12 | N4: =IF(Table2[[#This Row],[Monthly_Salary]]="","",Table2[[#This Row],[Monthly_Salary]]*Table2[[#This Row],[Num_Month_Final]]) -> 432000 | O4: 3 | P4: =IF(Table2[[#This Row],[Exp_Years]]<0,ABS(Table2[[#This Row],[Exp_Years]]),Table2[[#This Row],[Exp_Years]]) -> 3 | Q4: 3 | R4: 10000 | S4: =IF(Table2[[#This Row],[Performance_Rating]]>=3,Table2[[#This Row],[Monthly_Salary]]*0.3,"") -> 10800 | T4: 90 | U4: 5 | V4: 1 | W4: No | X4: Hybrid | Y4: =IF(Table2[[#This Row],[Work_Mode]]<>"",Table2[[#This Row],[Work_Mode]], IF(ISNUMBER(SEARCH("India",Table2[[#This Row],[Emp_Name]])),"Office", IF(ISNUMBER(SEARCH("Foreign",Table2[[#This Row],[Emp_Name]])),"Remote",""))) -> Hybrid | Z4: 10 | AA4: =IF(OR(Table2[[#This Row],[Role]]="Intern",Table2[[#This Row],[Role]]="Administrative Assistant",Table2[[#This Row],[Role]]="Analyst"), Table2[[#This Row],[Overtime_Hours]]*250, IF(OR(Table2[[#This Row],[Role]]="Senior Analyst",Table2[[#This Row],[Role]]="Specialist",Table2[[#This Row],[Role]]="Lead Analyst"), Table2[[#This Row],[Overtime_Hours]]*300, IF(OR(Table2[[#This Row],[Role]]="Manager",Table2[[#This Row],[Role]]="Senior Manager"), Table2[[#This Row],[Overtime_Hours]]*350, ""))) -> 3000 | AB4: Medium | AC4: =IF(COUNTIF(Table2[Emp_ID],Table2[[#This Row],[Emp_ID]])>1,"Duplicate","Unique") -> Unique | AD4: =_xlfn.TEXTJOIN("|",TRUE,Table2[[#This Row],[Emp_ID]:[Salary_Band]]) -> ZOM1377|Employee_377_India|25|Pune|Operations|Senior Analyst|INR|INR|36000|12|12|432000|3|3|3|10000|10800|90|5|1|No|Hybrid|Hybrid|10|3000|Medium | AE4: =IF(COUNTIFS(Table2[Emp_ID],Table2[[#This Row],[Emp_ID]],Table2[Row_Concat],Table2[[#This Row],[Row_Concat]])>1,"Exact Duplicate", IF(COUNTIF(Table2[Emp_ID],Table2[[#This Row],[Emp_ID]])>1,"Mismatch","Unique")) -> Unique | AF4: =ROW() -> 4 | AG4: =IF(Table2[[#This Row],[Monthly_Salary]]="","Exclude", IF(Table2[[#This Row],[Row_Status]]="Mismatch","Exclude", IF(AND(Table2[[#This Row],[Row_Status]]="Exact Duplicate", COUNTIFS(Table2[Emp_ID],Table2[[#This Row],[Emp_ID]],Table2[Row_Concat],Table2[[#This Row],[Row_Concat]], Table2[Row_Number],"<"&Table2[[#This Row],[Row_Number]])>=1),"Delete",""))) | AH4: =VLOOKUP(Table2[[#This Row],[Department]],Raw_2!A:B,2,0) -> Day | AI4: =VLOOKUP(Table2[[#This Row],[Department]],Raw_2!A:C,3,0) -> 14
A5: ZOM1076 | B5: Employee_76_India | C5: 27 | D5: M | E5: =IF(OR(Table2[[#This Row],[Gender]]="Male",Table2[[#This Row],[Gender]]="M"),"M", IF(OR(Table2[[#This Row],[Gender]]="Female",Table2[[#This Row],[Gender]]="F"),"F","")) -> M | F5: Gurugram | G5: Logistics | H5: Senior Analyst | I5: INR | J5: =IF(ISNUMBER(SEARCH("India",Table2[[#This Row],[Emp_Name]])),"INR", IF(ISNUMBER(SEARCH("Foreign",Table2[[#This Row],[Emp_Name]])),Table2[[#This Row],[Currency]],Table2[[#This Row],[Currency]])) -> INR | K5: 36000 | L5: 12 | M5: =IF(Table2[[#This Row],[Num_Month]]<>12,12,Table2[[#This Row],[Num_Month]]) -> 12 | N5: =IF(Table2[[#This Row],[Monthly_Salary]]="","",Table2[[#This Row],[Monthly_Salary]]*Table2[[#This Row],[Num_Month_Final]]) -> 432000 | O5: 3 | P5: =IF(Table2[[#This Row],[Exp_Years]]<0,ABS(Table2[[#This Row],[Exp_Years]]),Table2[[#This Row],[Exp_Years]]) -> 3 | Q5: 3 | R5: 8000 | S5: =IF(Table2[[#This Row],[Performance_Rating]]>=3,Table2[[#This Row],[Monthly_Salary]]*0.3,"") -> 10800 | T5: 80 | U5: 5 | V5: 3 | Y5: =IF(Table2[[#This Row],[Work_Mode]]<>"",Table2[[#This Row],[Work_Mode]], IF(ISNUMBER(SEARCH("India",Table2[[#This Row],[Emp_Name]])),"Office", IF(ISNUMBER(SEARCH("Foreign",Table2[[#This Row],[Emp_Name]])),"Remote",""))) -> Office | Z5: 10 | AA5: =IF(OR(Table2[[#This Row],[Role]]="Intern",Table2[[#This Row],[Role]]="Administrative Assistant",Table2[[#This Row],[Role]]="Analyst"), Table2[[#This Row],[Overtime_Hours]]*250, IF(OR(Table2[[#This Row],[Role]]="Senior Analyst",Table2[[#This Row],[Role]]="Specialist",Table2[[#This Row],[Role]]="Lead Analyst"), Table2[[#This Row],[Overtime_Hours]]*300, IF(OR(Table2[[#This Row],[Role]]="Manager",Table2[[#This Row],[Role]]="Senior Manager"), Table2[[#This Row],[Overtime_Hours]]*350, ""))) -> 3000 | AB5: Medium | AC5: =IF(COUNTIF(Table2[Emp_ID],Table2[[#This Row],[Emp_ID]])>1,"Duplicate","Unique") -> Unique | AD5: =_xlfn.TEXTJOIN("|",TRUE,Table2[[#This Row],[Emp_ID]:[Salary_Band]]) -> ZOM1076|Employee_76_India|27|M|M|Gurugram|Logistics|Senior Analyst|INR|INR|36000|12|12|432000|3|3|3|8000|10800|80|5|3|Office|10|3000|Medium | AE5: =IF(COUNTIFS(Table2[Emp_ID],Table2[[#This Row],[Emp_ID]],Table2[Row_Concat],Table2[[#This Row],[Row_Concat]])>1,"Exact Duplicate", IF(COUNTIF(Table2[Emp_ID],Table2[[#This Row],[Emp_ID]])>1,"Mismatch","Unique")) -> Unique | AF5: =ROW() -> 5 | AG5: =IF(Table2[[#This Row],[Monthly_Salary]]="","Exclude", IF(Table2[[#This Row],[Row_Status]]="Mismatch","Exclude", IF(AND(Table2[[#This Row],[Row_Status]]="Exact Duplicate", COUNTIFS(Table2[Emp_ID],Table2[[#This Row],[Emp_ID]],Table2[Row_Concat],Table2[[#This Row],[Row_Concat]], Table2[Row_Number],"<"&Table2[[#This Row],[Row_Number]])>=1),"Delete",""))) | AH5: =VLOOKUP(Table2[[#This Row],[Department]],Raw_2!A:B,2,0) -> Night | AI5: =VLOOKUP(Table2[[#This Row],[Department]],Raw_2!A:C,3,0) -> 13
A6: ZOM1103 | B6: Employee_103_India | C6: 27 | D6: M | E6: =IF(OR(Table2[[#This Row],[Gender]]="Male",Table2[[#This Row],[Gender]]="M"),"M", IF(OR(Table2[[#This Row],[Gender]]="Female",Table2[[#This Row],[Gender]]="F"),"F","")) -> M | F6: Delhi | G6: Logistics | H6: Senior Analyst | I6: INR | J6: =IF(ISNUMBER(SEARCH("India",Table2[[#This Row],[Emp_Name]])),"INR", IF(ISNUMBER(SEARCH("Foreign",Table2[[#This Row],[Emp_Name]])),Table2[[#This Row],[Currency]],Table2[[#This Row],[Currency]])) -> INR | K6: 49000 | L6: 12 | M6: =IF(Table2[[#This Row],[Num_Month]]<>12,12,Table2[[#This Row],[Num_Month]]) -> 12 | N6: =IF(Table2[[#This Row],[Monthly_Salary]]="","",Table2[[#This Row],[Monthly_Salary]]*Table2[[#This Row],[Num_Month_Final]]) -> 588000 | O6: -4 | P6: =IF(Table2[[#This Row],[Exp_Years]]<0,ABS(Table2[[#This Row],[Exp_Years]]),Table2[[#This Row],[Exp_Years]]) -> 4 | Q6: 2 | R6: 23300 | S6: =IF(Table2[[#This Row],[Performance_Rating]]>=3,Table2[[#This Row],[Monthly_Salary]]*0.3,"") | T6: 95 | U6: 5 | V6: 3 | W6: Yes | X6: Hybrid | Y6: =IF(Table2[[#This Row],[Work_Mode]]<>"",Table2[[#This Row],[Work_Mode]], IF(ISNUMBER(SEARCH("India",Table2[[#This Row],[Emp_Name]])),"Office", IF(ISNUMBER(SEARCH("Foreign",Table2[[#This Row],[Emp_Name]])),"Remote",""))) -> Hybrid | Z6: 5 | AA6: =IF(OR(Table2[[#This Row],[Role]]="Intern",Table2[[#This Row],[Role]]="Administrative Assistant",Table2[[#This Row],[Role]]="Analyst"), Table2[[#This Row],[Overtime_Hours]]*250, IF(OR(Table2[[#This Row],[Role]]="Senior Analyst",Table2[[#This Row],[Role]]="Specialist",Table2[[#This Row],[Role]]="Lead Analyst"), Table2[[#This Row],[Overtime_Hours]]*300, IF(OR(Table2[[#This Row],[Role]]="Manager",Table2[[#This Row],[Role]]="Senior Manager"), Table2[[#This Row],[Overtime_Hours]]*350, ""))) -> 1500 | AB6: Low | AC6: =IF(COUNTIF(Table2[Emp_ID],Table2[[#This Row],[Emp_ID]])>1,"Duplicate","Unique") -> Unique | AD6: =_xlfn.TEXTJOIN("|",TRUE,Table2[[#This Row],[Emp_ID]:[Salary_Band]]) -> ZOM1103|Employee_103_India|27|M|M|Delhi|Logistics|Senior Analyst|INR|INR|49000|12|12|588000|-4|4|2|23300|95|5|3|Yes|Hybrid|Hybrid|5|1500|Low | AE6: =IF(COUNTIFS(Table2[Emp_ID],Table2[[#This Row],[Emp_ID]],Table2[Row_Concat],Table2[[#This Row],[Row_Concat]])>1,"Exact Duplicate", IF(COUNTIF(Table2[Emp_ID],Table2[[#This Row],[Emp_ID]])>1,"Mismatch","Unique")) -> Unique | AF6: =ROW() -> 6 | AG6: =IF(Table2[[#This Row],[Monthly_Salary]]="","Exclude", IF(Table2[[#This Row],[Row_Status]]="Mismatch","Exclude", IF(AND(Table2[[#This Row],[Row_Status]]="Exact Duplicate", COUNTIFS(Table2[Emp_ID],Table2[[#This Row],[Emp_ID]],Table2[Row_Concat],Table2[[#This Row],[Row_Concat]], Table2[Row_Number],"<"&Table2[[#This Row],[Row_Number]])>=1),"Delete",""))) | AH6: =VLOOKUP(Table2[[#This Row],[Department]],Raw_2!A:B,2,0) -> Night | AI6: =VLOOKUP(Table2[[#This Row],[Department]],Raw_2!A:C,3,0) -> 13
A7: ZOM1014 | B7: Employee_14_India | C7: 27 | E7: =IF(OR(Table2[[#This Row],[Gender]]="Male",Table2[[#This Row],[Gender]]="M"),"M", IF(OR(Table2[[#This Row],[Gender]]="Female",Table2[[#This Row],[Gender]]="F"),"F","")) | F7: Delhi | G7: Analytics | H7: Senior Analyst | I7: INR | J7: =IF(ISNUMBER(SEARCH("India",Table2[[#This Row],[Emp_Name]])),"INR", IF(ISNUMBER(SEARCH("Foreign",Table2[[#This Row],[Emp_Name]])),Table2[[#This Row],[Currency]],Table2[[#This Row],[Currency]])) -> INR | K7: 51000 | L7: 12 | M7: =IF(Table2[[#This Row],[Num_Month]]<>12,12,Table2[[#This Row],[Num_Month]]) -> 12 | N7: =IF(Table2[[#This Row],[Monthly_Salary]]="","",Table2[[#This Row],[Monthly_Salary]]*Table2[[#This Row],[Num_Month_Final]]) -> 612000 | O7: 4 | P7: =IF(Table2[[#This Row],[Exp_Years]]<0,ABS(Table2[[#This Row],[Exp_Years]]),Table2[[#This Row],[Exp_Years]]) -> 4 | Q7: 3 | R7: 10000 | S7: =IF(Table2[[#This Row],[Performance_Rating]]>=3,Table2[[#This Row],[Monthly_Salary]]*0.3,"") -> 15300 | T7: 88 | U7: 5 | V7: 5 | X7: Hybrid | Y7: =IF(Table2[[#This Row],[Work_Mode]]<>"",Table2[[#This Row],[Work_Mode]], IF(ISNUMBER(SEARCH("India",Table2[[#This Row],[Emp_Name]])),"Office", IF(ISNUMBER(SEARCH("Foreign",Table2[[#This Row],[Emp_Name]])),"Remote",""))) -> Hybrid | AA7: =IF(OR(Table2[[#This Row],[Role]]="Intern",Table2[[#This Row],[Role]]="Administrative Assistant",Table2[[#This Row],[Role]]="Analyst"), Table2[[#This Row],[Overtime_Hours]]*250, IF(OR(Table2[[#This Row],[Role]]="Senior Analyst",Table2[[#This Row],[Role]]="Specialist",Table2[[#This Row],[Role]]="Lead Analyst"), Table2[[#This Row],[Overtime_Hours]]*300, IF(OR(Table2[[#This Row],[Role]]="Manager",Table2[[#This Row],[Role]]="Senior Manager"), Table2[[#This Row],[Overtime_Hours]]*350, ""))) -> 0 | AB7: Medium | AC7: =IF(COUNTIF(Table2[Emp_ID],Table2[[#This Row],[Emp_ID]])>1,"Duplicate","Unique") -> Unique | AD7: =_xlfn.TEXTJOIN("|",TRUE,Table2[[#This Row],[Emp_ID]:[Salary_Band]]) -> ZOM1014|Employee_14_India|27|Delhi|Analytics|Senior Analyst|INR|INR|51000|12|12|612000|4|4|3|10000|15300|88|5|5|Hybrid|Hybrid|0|Medium | AE7: =IF(COUNTIFS(Table2[Emp_ID],Table2[[#This Row],[Emp_ID]],Table2[Row_Concat],Table2[[#This Row],[Row_Concat]])>1,"Exact Duplicate", IF(COUNTIF(Table2[Emp_ID],Table2[[#This Row],[Emp_ID]])>1,"Mismatch","Unique")) -> Unique | AF7: =ROW() -> 7 | AG7: =IF(Table2[[#This Row],[Monthly_Salary]]="","Exclude", IF(Table2[[#This Row],[Row_Status]]="Mismatch","Exclude", IF(AND(Table2[[#This Row],[Row_Status]]="Exact Duplicate", COUNTIFS(Table2[Emp_ID],Table2[[#This Row],[Emp_ID]],Table2[Row_Concat],Table2[[#This Row],[Row_Concat]], Table2[Row_Number],"<"&Table2[[#This Row],[Row_Number]])>=1),"Delete",""))) | AH7: =VLOOKUP(Table2[[#This Row],[Department]],Raw_2!A:B,2,0) -> Day | AI7: =VLOOKUP(Table2[[#This Row],[Department]],Raw_2!A:C,3,0) -> 25
A8: ZOM1333 | B8: Employee_333_India | C8: 26 | D8: F | E8: =IF(OR(Table2[[#This Row],[Gender]]="Male",Table2[[#This Row],[Gender]]="M"),"M", IF(OR(Table2[[#This Row],[Gender]]="Female",Table2[[#This Row],[Gender]]="F"),"F","")) -> F | G8: Operations | H8: Senior Analyst | I8: INR | J8: =IF(ISNUMBER(SEARCH("India",Table2[[#This Row],[Emp_Name]])),"INR", IF(ISNUMBER(SEARCH("Foreign",Table2[[#This Row],[Emp_Name]])),Table2[[#This Row],[Currency]],Table2[[#This Row],[Currency]])) -> INR | K8: 42000 | L8: 12 | M8: =IF(Table2[[#This Row],[Num_Month]]<>12,12,Table2[[#This Row],[Num_Month]]) -> 12 | N8: =IF(Table2[[#This Row],[Monthly_Salary]]="","",Table2[[#This Row],[Monthly_Salary]]*Table2[[#This Row],[Num_Month_Final]]) -> 504000 | O8: 3 | P8: =IF(Table2[[#This Row],[Exp_Years]]<0,ABS(Table2[[#This Row],[Exp_Years]]),Table2[[#This Row],[Exp_Years]]) -> 3 | Q8: 1 | R8: 23400 | S8: =IF(Table2[[#This Row],[Performance_Rating]]>=3,Table2[[#This Row],[Monthly_Salary]]*0.3,"") | T8: 95 | U8: 15 | V8: 5 | W8: No | X8: Hybrid | Y8: =IF(Table2[[#This Row],[Work_Mode]]<>"",Table2[[#This Row],[Work_Mode]], IF(ISNUMBER(SEARCH("India",Table2[[#This Row],[Emp_Name]])),"Office", IF(ISNUMBER(SEARCH("Foreign",Table2[[#This Row],[Emp_Name]])),"Remote",""))) -> Hybrid | Z8: 10 | AA8: =IF(OR(Table2[[#This Row],[Role]]="Intern",Table2[[#This Row],[Role]]="Administrative Assistant",Table2[[#This Row],[Role]]="Analyst"), Table2[[#This Row],[Overtime_Hours]]*250, IF(OR(Table2[[#This Row],[Role]]="Senior Analyst",Table2[[#This Row],[Role]]="Specialist",Table2[[#This Row],[Role]]="Lead Analyst"), Table2[[#This Row],[Overtime_Hours]]*300, IF(OR(Table2[[#This Row],[Role]]="Manager",Table2[[#This Row],[Role]]="Senior Manager"), Table2[[#This Row],[Overtime_Hours]]*350, ""))) -> 3000 | AB8: Low | AC8: =IF(COUNTIF(Table2[Emp_ID],Table2[[#This Row],[Emp_ID]])>1,"Duplicate","Unique") -> Unique | AD8: =_xlfn.TEXTJOIN("|",TRUE,Table2[[#This Row],[Emp_ID]:[Salary_Band]]) -> ZOM1333|Employee_333_India|26|F|F|Operations|Senior Analyst|INR|INR|42000|12|12|504000|3|3|1|23400|95|15|5|No|Hybrid|Hybrid|10|3000|Low | AE8: =IF(COUNTIFS(Table2[Emp_ID],Table2[[#This Row],[Emp_ID]],Table2[Row_Concat],Table2[[#This Row],[Row_Concat]])>1,"Exact Duplicate", IF(COUNTIF(Table2[Emp_ID],Table2[[#This Row],[Emp_ID]])>1,"Mismatch","Unique")) -> Unique | AF8: =ROW() -> 8 | AG8: =IF(Table2[[#This Row],[Monthly_Salary]]="","Exclude", IF(Table2[[#This Row],[Row_Status]]="Mismatch","Exclude", IF(AND(Table2[[#This Row],[Row_Status]]="Exact Duplicate", COUNTIFS(Table2[Emp_ID],Table2[[#This Row],[Emp_ID]],Table2[Row_Concat],Table2[[#This Row],[Row_Concat]], Table2[Row_Number],"<"&Table2[[#This Row],[Row_Number]])>=1),"Delete",""))) | AH8: =VLOOKUP(Table2[[#This Row],[Department]],Raw_2!A:B,2,0) -> Day | AI8: =VLOOKUP(Table2[[#This Row],[Department]],Raw_2!A:C,3,0) -> 14
A9: ZOM1625 | B9: Employee_25_India | C9: 25 | D9: Female | E9: =IF(OR(Table2[[#This Row],[Gender]]="Male",Table2[[#This Row],[Gender]]="M"),"M", IF(OR(Table2[[#This Row],[Gender]]="Female",Table2[[#This Row],[Gender]]="F"),"F","")) -> F | F9: Chennai | G9: Operations | H9: Senior Analyst | I9: USD | J9: =IF(ISNUMBER(SEARCH("India",Table2[[#This Row],[Emp_Name]])),"INR", IF(ISNUMBER(SEARCH("Foreign",Table2[[#This Row],[Emp_Name]])),Table2[[#This Row],[Currency]],Table2[[#This Row],[Currency]])) -> INR | K9: 36000 | L9: 12 | M9: =IF(Table2[[#This Row],[Num_Month]]<>12,12,Table2[[#This Row],[Num_Month]]) -> 12 | N9: =IF(Table2[[#This Row],[Monthly_Salary]]="","",Table2[[#This Row],[Monthly_Salary]]*Table2[[#This Row],[Num_Month_Final]]) -> 432000 | O9: 3 | P9: =IF(Table2[[#This Row],[Exp_Years]]<0,ABS(Table2[[#This Row],[Exp_Years]]),Table2[[#This Row],[Exp_Years]]) -> 3 | Q9: 4 | R9: 15000 | S9: =IF(Table2[[#This Row],[Performance_Rating]]>=3,Table2[[#This Row],[Monthly_Salary]]*0.3,"") -> 10800 | T9: 80 | U9: 7 | V9: 5 | X9: Remote | Y9: =IF(Table2[[#This Row],[Work_Mode]]<>"",Table2[[#This Row],[Work_Mode]], IF(ISNUMBER(SEARCH("India",Table2[[#This Row],[Emp_Name]])),"Office", IF(ISNUMBER(SEARCH("Foreign",Table2[[#This Row],[Emp_Name]])),"Remote",""))) -> Remote | AA9: =IF(OR(Table2[[#This Row],[Role]]="Intern",Table2[[#This Row],[Role]]="Administrative Assistant",Table2[[#This Row],[Role]]="Analyst"), Table2[[#This Row],[Overtime_Hours]]*250, IF(OR(Table2[[#This Row],[Role]]="Senior Analyst",Table2[[#This Row],[Role]]="Specialist",Table2[[#This Row],[Role]]="Lead Analyst"), Table2[[#This Row],[Overtime_Hours]]*300, IF(OR(Table2[[#This Row],[Role]]="Manager",Table2[[#This Row],[Role]]="Senior Manager"), Table2[[#This Row],[Overtime_Hours]]*350, ""))) -> 0 | AB9: High | AC9: =IF(COUNTIF(Table2[Emp_ID],Table2[[#This Row],[Emp_ID]])>1,"Duplicate","Unique") -> Duplicate | AD9: =_xlfn.TEXTJOIN("|",TRUE,Table2[[#This Row],[Emp_ID]:[Salary_Band]]) -> ZOM1625|Employee_25_India|25|Female|F|Chennai|Operations|Senior Analyst|USD|INR|36000|12|12|432000|3|3|4|15000|10800|80|7|5|Remote|Remote|0|High | AE9: =IF(COUNTIFS(Table2[Emp_ID],Table2[[#This Row],[Emp_ID]],Table2[Row_Concat],Table2[[#This Row],[Row_Concat]])>1,"Exact Duplicate", IF(COUNTIF(Table2[Emp_ID],Table2[[#This Row],[Emp_ID]])>1,"Mismatch","Unique")) -> Exact Duplicate | AF9: =ROW() -> 9 | AG9: =IF(Table2[[#This Row],[Monthly_Salary]]="","Exclude", IF(Table2[[#This Row],[Row_Status]]="Mismatch","Exclude", IF(AND(Table2[[#This Row],[Row_Status]]="Exact Duplicate", COUNTIFS(Table2[Emp_ID],Table2[[#This Row],[Emp_ID]],Table2[Row_Concat],Table2[[#This Row],[Row_Concat]], Table2[Row_Number],"<"&Table2[[#This Row],[Row_Number]])>=1),"Delete",""))) | AH9: =VLOOKUP(Table2[[#This Row],[Department]],Raw_2!A:B,2,0) -> Day | AI9: =VLOOKUP(Table2[[#This Row],[Department]],Raw_2!A:C,3,0) -> 14
A10: ZOM1005 | B10: Employee_5_India | C10: 26 | E10: =IF(OR(Table2[[#This Row],[Gender]]="Male",Table2[[#This Row],[Gender]]="M"),"M", IF(OR(Table2[[#This Row],[Gender]]="Female",Table2[[#This Row],[Gender]]="F"),"F","")) | F10: Hyderabad | G10: Operations | H10: Senior Analyst | I10: INR | J10: =IF(ISNUMBER(SEARCH("India",Table2[[#This Row],[Emp_Name]])),"INR", IF(ISNUMBER(SEARCH("Foreign",Table2[[#This Row],[Emp_Name]])),Table2[[#This Row],[Currency]],Table2[[#This Row],[Currency]])) -> INR | K10: 42333 | L10: 12 | M10: =IF(Table2[[#This Row],[Num_Month]]<>12,12,Table2[[#This Row],[Num_Month]]) -> 12 | N10: =IF(Table2[[#This Row],[Monthly_Salary]]="","",Table2[[#This Row],[Monthly_Salary]]*Table2[[#This Row],[Num_Month_Final]]) -> 507996 | O10: 3 | P10: =IF(Table2[[#This Row],[Exp_Years]]<0,ABS(Table2[[#This Row],[Exp_Years]]),Table2[[#This Row],[Exp_Years]]) -> 3 | Q10: 4 | R10: 15000 | S10: =IF(Table2[[#This Row],[Performance_Rating]]>=3,Table2[[#This Row],[Monthly_Salary]]*0.3,"") -> 12699.9 | T10: 85 | U10: 10 | V10: 3 | Y10: =IF(Table2[[#This Row],[Work_Mode]]<>"",Table2[[#This Row],[Work_Mode]], IF(ISNUMBER(SEARCH("India",Table2[[#This Row],[Emp_Name]])),"Office", IF(ISNUMBER(SEARCH("Foreign",Table2[[#This Row],[Emp_Name]])),"Remote",""))) -> Office | Z10: 5 | AA10: =IF(OR(Table2[[#This Row],[Role]]="Intern",Table2[[#This Row],[Role]]="Administrative Assistant",Table2[[#This Row],[Role]]="Analyst"), Table2[[#This Row],[Overtime_Hours]]*250, IF(OR(Table2[[#This Row],[Role]]="Senior Analyst",Table2[[#This Row],[Role]]="Specialist",Table2[[#This Row],[Role]]="Lead Analyst"), Table2[[#This Row],[Overtime_Hours]]*300, IF(OR(Table2[[#This Row],[Role]]="Manager",Table2[[#This Row],[Role]]="Senior Manager"), Table2[[#This Row],[Overtime_Hours]]*350, ""))) -> 1500 | AB10: Medium | AC10: =IF(COUNTIF(Table2[Emp_ID],Table2[[#This Row],[Emp_ID]])>1,"Duplicate","Unique") -> Unique | AD10: =_xlfn.TEXTJOIN("|",TRUE,Table2[[#This Row],[Emp_ID]:[Salary_Band]]) -> ZOM1005|Employee_5_India|26|Hyderabad|Operations|Senior Analyst|INR|INR|42333|12|12|507996|3|3|4|15000|12699.9|85|10|3|Office|5|1500|Medium | AE10: =IF(COUNTIFS(Table2[Emp_ID],Table2[[#This Row],[Emp_ID]],Table2[Row_Concat],Table2[[#This Row],[Row_Concat]])>1,"Exact Duplicate", IF(COUNTIF(Table2[Emp_ID],Table2[[#This Row],[Emp_ID]])>1,"Mismatch","Unique")) -> Unique | AF10: =ROW() -> 10 | AG10: =IF(Table2[[#This Row],[Monthly_Salary]]="","Exclude", IF(Table2[[#This Row],[Row_Status]]="Mismatch","Exclude", IF(AND(Table2[[#This Row],[Row_Status]]="Exact Duplicate", COUNTIFS(Table2[Emp_ID],Table2[[#This Row],[Emp_ID]],Table2[Row_Concat],Table2[[#This Row],[Row_Concat]], Table2[Row_Number],"<"&Table2[[#This Row],[Row_Number]])>=1),"Delete",""))) | AH10: =VLOOKUP(Table2[[#This Row],[Department]],Raw_2!A:B,2,0) -> Day | AI10: =VLOOKUP(Table2[[#This Row],[Department]],Raw_2!A:C,3,0) -> 14
A11: ZOM1570 | B11: Employee_570_India | C11: 26 | D11: F | E11: =IF(OR(Table2[[#This Row],[Gender]]="Male",Table2[[#This Row],[Gender]]="M"),"M", IF(OR(Table2[[#This Row],[Gender]]="Female",Table2[[#This Row],[Gender]]="F"),"F","")) -> F | F11: Mumbai | G11: Logistics | H11: Senior Analyst | I11: INR | J11: =IF(ISNUMBER(SEARCH("India",Table2[[#This Row],[Emp_Name]])),"INR", IF(ISNUMBER(SEARCH("Foreign",Table2[[#This Row],[Emp_Name]])),Table2[[#This Row],[Currency]],Table2[[#This Row],[Currency]])) -> INR | K11: 48000 | L11: 12 | M11: =IF(Table2[[#This Row],[Num_Month]]<>12,12,Table2[[#This Row],[Num_Month]]) -> 12 | N11: =IF(Table2[[#This Row],[Monthly_Salary]]="","",Table2[[#This Row],[Monthly_Salary]]*Table2[[#This Row],[Num_Month_Final]]) -> 576000 | O11: 4 | P11: =IF(Table2[[#This Row],[Exp_Years]]<0,ABS(Table2[[#This Row],[Exp_Years]]),Table2[[#This Row],[Exp_Years]]) -> 4 | Q11: 1 | R11: 24000 | S11: =IF(Table2[[#This Row],[Performance_Rating]]>=3,Table2[[#This Row],[Monthly_Salary]]*0.3,"") | T11: 88 | U11: 7 | V11: 1 | W11: No | X11: Office | Y11: =IF(Table2[[#This Row],[Work_Mode]]<>"",Table2[[#This Row],[Work_Mode]], IF(ISNUMBER(SEARCH("India",Table2[[#This Row],[Emp_Name]])),"Office", IF(ISNUMBER(SEARCH("Foreign",Table2[[#This Row],[Emp_Name]])),"Remote",""))) -> Office | AA11: =IF(OR(Table2[[#This Row],[Role]]="Intern",Table2[[#This Row],[Role]]="Administrative Assistant",Table2[[#This Row],[Role]]="Analyst"), Table2[[#This Row],[Overtime_Hours]]*250, IF(OR(Table2[[#This Row],[Role]]="Senior Analyst",Table2[[#This Row],[Role]]="Specialist",Table2[[#This Row],[Role]]="Lead Analyst"), Table2[[#This Row],[Overtime_Hours]]*300, IF(OR(Table2[[#This Row],[Role]]="Manager",Table2[[#This Row],[Role]]="Senior Manager"), Table2[[#This Row],[Overtime_Hours]]*350, ""))) -> 0 | AB11: Low | AC11: =IF(COUNTIF(Table2[Emp_ID],Table2[[#This Row],[Emp_ID]])>1,"Duplicate","Unique") -> Unique | AD11: =_xlfn.TEXTJOIN("|",TRUE,Table2[[#This Row],[Emp_ID]:[Salary_Band]]) -> ZOM1570|Employee_570_India|26|F|F|Mumbai|Logistics|Senior Analyst|INR|INR|48000|12|12|576000|4|4|1|24000|88|7|1|No|Office|Office|0|Low | AE11: =IF(COUNTIFS(Table2[Emp_ID],Table2[[#This Row],[Emp_ID]],Table2[Row_Concat],Table2[[#This Row],[Row_Concat]])>1,"Exact Duplicate", IF(COUNTIF(Table2[Emp_ID],Table2[[#This Row],[Emp_ID]])>1,"Mismatch","Unique")) -> Unique | AF11: =ROW() -> 11 | AG11: =IF(Table2[[#This Row],[Monthly_Salary]]="","Exclude", IF(Table2[[#This Row],[Row_Status]]="Mismatch","Exclude", IF(AND(Table2[[#This Row],[Row_Status]]="Exact Duplicate", COUNTIFS(Table2[Emp_ID],Table2[[#This Row],[Emp_ID]],Table2[Row_Concat],Table2[[#This Row],[Row_Concat]], Table2[Row_Number],"<"&Table2[[#This Row],[Row_Number]])>=1),"Delete",""))) | AH11: =VLOOKUP(Table2[[#This Row],[Department]],Raw_2!A:B,2,0) -> Night | AI11: =VLOOKUP(Table2[[#This Row],[Department]],Raw_2!A:C,3,0) -> 13
A12: ZOM1142 | B12: Employee_142_India | C12: 26 | D12: F | E12: =IF(OR(Table2[[#This Row],[Gender]]="Male",Table2[[#This Row],[Gender]]="M"),"M", IF(OR(Table2[[#This Row],[Gender]]="Female",Table2[[#This Row],[Gender]]="F"),"F","")) -> F | F12: Kolkata | G12: Customer Support | H12: Senior Analyst | I12: INR | J12: =IF(ISNUMBER(SEARCH("India",Table2[[#This Row],[Emp_Name]])),"INR", IF(ISNUMBER(SEARCH("Foreign",Table2[[#This Row],[Emp_Name]])),Table2[[#This Row],[Currency]],Table2[[#This Row],[Currency]])) -> INR | K12: 48000 | L12: 13 | M12: =IF(Table2[[#This Row],[Num_Month]]<>12,12,Table2[[#This Row],[Num_Month]]) -> 12 | N12: =IF(Table2[[#This Row],[Monthly_Salary]]="","",Table2[[#This Row],[Monthly_Salary]]*Table2[[#This Row],[Num_Month_Final]]) -> 576000 | O12: 4 | P12: =IF(Table2[[#This Row],[Exp_Years]]<0,ABS(Table2[[#This Row],[Exp_Years]]),Table2[[#This Row],[Exp_Years]]) -> 4 | Q12: 4 | R12: 15000 | S12: =IF(Table2[[#This Row],[Performance_Rating]]>=3,Table2[[#This Row],[Monthly_Salary]]*0.3,"") -> 14400 | T12: 90 | U12: 10 | V12: 1 | W12: Yes | X12: Hybrid | Y12: =IF(Table2[[#This Row],[Work_Mode]]<>"",Table2[[#This Row],[Work_Mode]], IF(ISNUMBER(SEARCH("India",Table2[[#This Row],[Emp_Name]])),"Office", IF(ISNUMBER(SEARCH("Foreign",Table2[[#This Row],[Emp_Name]])),"Remote",""))) -> Hybrid | Z12: 5 | AA12: =IF(OR(Table2[[#This Row],[Role]]="Intern",Table2[[#This Row],[Role]]="Administrative Assistant",Table2[[#This Row],[Role]]="Analyst"), Table2[[#This Row],[Overtime_Hours]]*250, IF(OR(Table2[[#This Row],[Role]]="Senior Analyst",Table2[[#This Row],[Role]]="Specialist",Table2[[#This Row],[Role]]="Lead Analyst"), Table2[[#This Row],[Overtime_Hours]]*300, IF(OR(Table2[[#This Row],[Role]]="Manager",Table2[[#This Row],[Role]]="Senior Manager"), Table2[[#This Row],[Overtime_Hours]]*350, ""))) -> 1500 | AB12: Medium | AC12: =IF(COUNTIF(Table2[Emp_ID],Table2[[#This Row],[Emp_ID]])>1,"Duplicate","Unique") -> Unique | AD12: =_xlfn.TEXTJOIN("|",TRUE,Table2[[#This Row],[Emp_ID]:[Salary_Band]]) -> ZOM1142|Employee_142_India|26|F|F|Kolkata|Customer Support|Senior Analyst|INR|INR|48000|13|12|576000|4|4|4|15000|14400|90|10|1|Yes|Hybrid|Hybrid|5|1500|Medium | AE12: =IF(COUNTIFS(Table2[Emp_ID],Table2[[#This Row],[Emp_ID]],Table2[Row_Concat],Table2[[#This Row],[Row_Concat]])>1,"Exact Duplicate", IF(COUNTIF(Table2[Emp_ID],Table2[[#This Row],[Emp_ID]])>1,"Mismatch","Unique")) -> Unique | AF12: =ROW() -> 12 | AG12: =IF(Table2[[#This Row],[Monthly_Salary]]="","Exclude", IF(Table2[[#This Row],[Row_Status]]="Mismatch","Exclude", IF(AND(Table2[[#This Row],[Row_Status]]="Exact Duplicate", COUNTIFS(Table2[Emp_ID],Table2[[#This Row],[Emp_ID]],Table2[Row_Concat],Table2[[#This Row],[Row_Concat]], Table2[Row_Number],"<"&Table2[[#This Row],[Row_Number]])>=1),"Delete",""))) | AH12: =VLOOKUP(Table2[[#This Row],[Department]],Raw_2!A:B,2,0) -> Day | AI12: =VLOOKUP(Table2[[#This Row],[Department]],Raw_2!A:C,3,0) -> 12
A13: ZOM1507 | B13: Employee_507_India | C13: 26 | D13: Female | E13: =IF(OR(Table2[[#This Row],[Gender]]="Male",Table2[[#This Row],[Gender]]="M"),"M", IF(OR(Table2[[#This Row],[Gender]]="Female",Table2[[#This Row],[Gender]]="F"),"F","")) -> F | F13: Noida | G13: Customer Support | H13: Senior Analyst | I13: INR | J13: =IF(ISNUMBER(SEARCH("India",Table2[[#This Row],[Emp_Name]])),"INR", IF(ISNUMBER(SEARCH("Foreign",Table2[[#This Row],[Emp_Name]])),Table2[[#This Row],[Currency]],Table2[[#This Row],[Currency]])) -> INR | K13: 31000 | L13: 12 | M13: =IF(Table2[[#This Row],[Num_Month]]<>12,12,Table2[[#This Row],[Num_Month]]) -> 12 | N13: =IF(Table2[[#This Row],[Monthly_Salary]]="","",Table2[[#This Row],[Monthly_Salary]]*Table2[[#This Row],[Num_Month_Final]]) -> 372000 | O13: 2 | P13: =IF(Table2[[#This Row],[Exp_Years]]<0,ABS(Table2[[#This Row],[Exp_Years]]),Table2[[#This Row],[Exp_Years]]) -> 2 | Q13: 5 | R13: 19000 | S13: =IF(Table2[[#This Row],[Performance_Rating]]>=3,Table2[[#This Row],[Monthly_Salary]]*0.3,"") -> 9300 | T13: 85 | U13: 7 | V13: 5 | X13: Hybrid | Y13: =IF(Table2[[#This Row],[Work_Mode]]<>"",Table2[[#This Row],[Work_Mode]], IF(ISNUMBER(SEARCH("India",Table2[[#This Row],[Emp_Name]])),"Office", IF(ISNUMBER(SEARCH("Foreign",Table2[[#This Row],[Emp_Name]])),"Remote",""))) -> Hybrid | Z13: 20 | AA13: =IF(OR(Table2[[#This Row],[Role]]="Intern",Table2[[#This Row],[Role]]="Administrative Assistant",Table2[[#This Row],[Role]]="Analyst"), Table2[[#This Row],[Overtime_Hours]]*250, IF(OR(Table2[[#This Row],[Role]]="Senior Analyst",Table2[[#This Row],[Role]]="Specialist",Table2[[#This Row],[Role]]="Lead Analyst"), Table2[[#This Row],[Overtime_Hours]]*300, IF(OR(Table2[[#This Row],[Role]]="Manager",Table2[[#This Row],[Role]]="Senior Manager"), Table2[[#This Row],[Overtime_Hours]]*350, ""))) -> 6000 | AB13: High | AC13: =IF(COUNTIF(Table2[Emp_ID],Table2[[#This Row],[Emp_ID]])>1,"Duplicate","Unique") -> Unique | AD13: =_xlfn.TEXTJOIN("|",TRUE,Table2[[#This Row],[Emp_ID]:[Salary_Band]]) -> ZOM1507|Employee_507_India|26|Female|F|Noida|Customer Support|Senior Analyst|INR|INR|31000|12|12|372000|2|2|5|19000|9300|85|7|5|Hybrid|Hybrid|20|6000|High | AE13: =IF(COUNTIFS(Table2[Emp_ID],Table2[[#This Row],[Emp_ID]],Table2[Row_Concat],Table2[[#This Row],[Row_Concat]])>1,"Exact Duplicate", IF(COUNTIF(Table2[Emp_ID],Table2[[#This Row],[Emp_ID]])>1,"Mismatch","Unique")) -> Unique | AF13: =ROW() -> 13 | AG13: =IF(Table2[[#This Row],[Monthly_Salary]]="","Exclude", IF(Table2[[#This Row],[Row_Status]]="Mismatch","Exclude", IF(AND(Table2[[#This Row],[Row_Status]]="Exact Duplicate", COUNTIFS(Table2[Emp_ID],Table2[[#This Row],[Emp_ID]],Table2[Row_Concat],Table2[[#This Row],[Row_Concat]], Table2[Row_Number],"<"&Table2[[#This Row],[Row_Number]])>=1),"Delete",""))) | AH13: =VLOOKUP(Table2[[#This Row],[Department]],Raw_2!A:B,2,0) -> Day | AI13: =VLOOKUP(Table2[[#This Row],[Department]],Raw_2!A:C,3,0) -> 12
A14: ZOM1068 | B14: Employee_68_India | C14: 27 | E14: =IF(OR(Table2[[#This Row],[Gender]]="Male",Table2[[#This Row],[Gender]]="M"),"M", IF(OR(Table2[[#This Row],[Gender]]="Female",Table2[[#This Row],[Gender]]="F"),"F","")) | F14: Indore | G14: Operations | H14: Senior Analyst | I14: INR | J14: =IF(ISNUMBER(SEARCH("India",Table2[[#This Row],[Emp_Name]])),"INR", IF(ISNUMBER(SEARCH("Foreign",Table2[[#This Row],[Emp_Name]])),Table2[[#This Row],[Currency]],Table2[[#This Row],[Currency]])) -> INR | K14: 35000 | L14: 12 | M14: =IF(Table2[[#This Row],[Num_Month]]<>12,12,Table2[[#This Row],[Num_Month]]) -> 12 | N14: =IF(Table2[[#This Row],[Monthly_Salary]]="","",Table2[[#This Row],[Monthly_Salary]]*Table2[[#This Row],[Num_Month_Final]]) -> 420000 | O14: 3 | P14: =IF(Table2[[#This Row],[Exp_Years]]<0,ABS(Table2[[#This Row],[Exp_Years]]),Table2[[#This Row],[Exp_Years]]) -> 3 | Q14: 1 | S14: =IF(Table2[[#This Row],[Performance_Rating]]>=3,Table2[[#This Row],[Monthly_Salary]]*0.3,"") | T14: 90 | U14: 5 | V14: 3 | W14: No | X14: Hybrid | Y14: =IF(Table2[[#This Row],[Work_Mode]]<>"",Table2[[#This Row],[Work_Mode]], IF(ISNUMBER(SEARCH("India",Table2[[#This Row],[Emp_Name]])),"Office", IF(ISNUMBER(SEARCH("Foreign",Table2[[#This Row],[Emp_Name]])),"Remote",""))) -> Hybrid | AA14: =IF(OR(Table2[[#This Row],[Role]]="Intern",Table2[[#This Row],[Role]]="Administrative Assistant",Table2[[#This Row],[Role]]="Analyst"), Table2[[#This Row],[Overtime_Hours]]*250, IF(OR(Table2[[#This Row],[Role]]="Senior Analyst",Table2[[#This Row],[Role]]="Specialist",Table2[[#This Row],[Role]]="Lead Analyst"), Table2[[#This Row],[Overtime_Hours]]*300, IF(OR(Table2[[#This Row],[Role]]="Manager",Table2[[#This Row],[Role]]="Senior Manager"), Table2[[#This Row],[Overtime_Hours]]*350, ""))) -> 0 | AB14: Low | AC14: =IF(COUNTIF(Table2[Emp_ID],Table2[[#This Row],[Emp_ID]])>1,"Duplicate","Unique") -> Unique | AD14: =_xlfn.TEXTJOIN("|",TRUE,Table2[[#This Row],[Emp_ID]:[Salary_Band]]) -> ZOM1068|Employee_68_India|27|Indore|Operations|Senior Analyst|INR|INR|35000|12|12|420000|3|3|1|90|5|3|No|Hybrid|Hybrid|0|Low | AE14: =IF(COUNTIFS(Table2[Emp_ID],Table2[[#This Row],[Emp_ID]],Table2[Row_Concat],Table2[[#This Row],[Row_Concat]])>1,"Exact Duplicate", IF(COUNTIF(Table2[Emp_ID],Table2[[#This Row],[Emp_ID]])>1,"Mismatch","Unique")) -> Unique | AF14: =ROW() -> 14 | AG14: =IF(Table2[[#This Row],[Monthly_Salary]]="","Exclude", IF(Table2[[#This Row],[Row_Status]]="Mismatch","Exclude", IF(AND(Table2[[#This Row],[Row_Status]]="Exact Duplicate", COUNTIFS(Table2[Emp_ID],Table2[[#This Row],[Emp_ID]],Table2[Row_Concat],Table2[[#This Row],[Row_Concat]], Table2[Row_Number],"<"&Table2[[#This Row],[Row_Number]])>=1),"Delete",""))) | AH14: =VLOOKUP(Table2[[#This Row],[Department]],Raw_2!A:B,2,0) -> Day | AI14: =VLOOKUP(Table2[[#This Row],[Department]],Raw_2!A:C,3,0) -> 14
A15: ZOM1372 | B15: Employee_372_India | C15: 25 | D15: F | E15: =IF(OR(Table2[[#This Row],[Gender]]="Male",Table2[[#This Row],[Gender]]="M"),"M", IF(OR(Table2[[#This Row],[Gender]]="Female",Table2[[#This Row],[Gender]]="F"),"F","")) -> F | F15: Kolkata | G15: HR | H15: Senior Analyst | I15: INR | J15: =IF(ISNUMBER(SEARCH("India",Table2[[#This Row],[Emp_Name]])),"INR", IF(ISNUMBER(SEARCH("Foreign",Table2[[#This Row],[Emp_Name]])),Table2[[#This Row],[Currency]],Table2[[#This Row],[Currency]])) -> INR | K15: 38000 | L15: 12 | M15: =IF(Table2[[#This Row],[Num_Month]]<>12,12,Table2[[#This Row],[Num_Month]]) -> 12 | N15: =IF(Table2[[#This Row],[Monthly_Salary]]="","",Table2[[#This Row],[Monthly_Salary]]*Table2[[#This Row],[Num_Month_Final]]) -> 456000 | O15: 3 | P15: =IF(Table2[[#This Row],[Exp_Years]]<0,ABS(Table2[[#This Row],[Exp_Years]]),Table2[[#This Row],[Exp_Years]]) -> 3 | Q15: 5 | R15: 24000 | S15: =IF(Table2[[#This Row],[Performance_Rating]]>=3,Table2[[#This Row],[Monthly_Salary]]*0.3,"") -> 11400 | T15: 90 | U15: 15 | V15: 5 | X15: Hybrid | Y15: =IF(Table2[[#This Row],[Work_Mode]]<>"",Table2[[#This Row],[Work_Mode]], IF(ISNUMBER(SEARCH("India",Table2[[#This Row],[Emp_Name]])),"Office", IF(ISNUMBER(SEARCH("Foreign",Table2[[#This Row],[Emp_Name]])),"Remote",""))) -> Hybrid | AA15: =IF(OR(Table2[[#This Row],[Role]]="Intern",Table2[[#This Row],[Role]]="Administrative Assistant",Table2[[#This Row],[Role]]="Analyst"), Table2[[#This Row],[Overtime_Hours]]*250, IF(OR(Table2[[#This Row],[Role]]="Senior Analyst",Table2[[#This Row],[Role]]="Specialist",Table2[[#This Row],[Role]]="Lead Analyst"), Table2[[#This Row],[Overtime_Hours]]*300, IF(OR(Table2[[#This Row],[Role]]="Manager",Table2[[#This Row],[Role]]="Senior Manager"), Table2[[#This Row],[Overtime_Hours]]*350, ""))) -> 0 | AB15: High | AC15: =IF(COUNTIF(Table2[Emp_ID],Table2[[#This Row],[Emp_ID]])>1,"Duplicate","Unique") -> Unique | AD15: =_xlfn.TEXTJOIN("|",TRUE,Table2[[#This Row],[Emp_ID]:[Salary_Band]]) -> ZOM1372|Employee_372_India|25|F|F|Kolkata|HR|Senior Analyst|INR|INR|38000|12|12|456000|3|3|5|24000|11400|90|15|5|Hybrid|Hybrid|0|High | AE15: =IF(COUNTIFS(Table2[Emp_ID],Table2[[#This Row],[Emp_ID]],Table2[Row_Concat],Table2[[#This Row],[Row_Concat]])>1,"Exact Duplicate", IF(COUNTIF(Table2[Emp_ID],Table2[[#This Row],[Emp_ID]])>1,"Mismatch","Unique")) -> Unique | AF15: =ROW() -> 15 | AG15: =IF(Table2[[#This Row],[Monthly_Salary]]="","Exclude", IF(Table2[[#This Row],[Row_Status]]="Mismatch","Exclude", IF(AND(Table2[[#This Row],[Row_Status]]="Exact Duplicate", COUNTIFS(Table2[Emp_ID],Table2[[#This Row],[Emp_ID]],Table2[Row_Concat],Table2[[#This Row],[Row_Concat]], Table2[Row_Number],"<"&Table2[[#This Row],[Row_Number]])>=1),"Delete",""))) | AH15: =VLOOKUP(Table2[[#This Row],[Department]],Raw_2!A:B,2,0) -> Day | AI15: =VLOOKUP(Table2[[#This Row],[Department]],Raw_2!A:C,3,0) -> 10
A16: ZOM1451 | B16: Employee_451_India | C16: 26 | E16: =IF(OR(Table2[[#This Row],[Gender]]="Male",Table2[[#This Row],[Gender]]="M"),"M", IF(OR(Table2[[#This Row],[Gender]]="Female",Table2[[#This Row],[Gender]]="F"),"F","")) | F16: Gurugram | G16: Analytics | H16: Senior Analyst | I16: INR | J16: =IF(ISNUMBER(SEARCH("India",Table2[[#This Row],[Emp_Name]])),"INR", IF(ISNUMBER(SEARCH("Foreign",Table2[[#This Row],[Emp_Name]])),Table2[[#This Row],[Currency]],Table2[[#This Row],[Currency]])) -> INR | K16: 48000 | L16: 12 | M16: =IF(Table2[[#This Row],[Num_Month]]<>12,12,Table2[[#This Row],[Num_Month]]) -> 12 | N16: =IF(Table2[[#This Row],[Monthly_Salary]]="","",Table2[[#This Row],[Monthly_Salary]]*Table2[[#This Row],[Num_Month_Final]]) -> 576000 | O16: 4 | P16: =IF(Table2[[#This Row],[Exp_Years]]<0,ABS(Table2[[#This Row],[Exp_Years]]),Table2[[#This Row],[Exp_Years]]) -> 4 | Q16: 4 | R16: 15000 | S16: =IF(Table2[[#This Row],[Performance_Rating]]>=3,Table2[[#This Row],[Monthly_Salary]]*0.3,"") -> 14400 | T16: 90 | U16: 15 | V16: 1 | W16: Yes | X16: Hybrid | Y16: =IF(Table2[[#This Row],[Work_Mode]]<>"",Table2[[#This Row],[Work_Mode]], IF(ISNUMBER(SEARCH("India",Table2[[#This Row],[Emp_Name]])),"Office", IF(ISNUMBER(SEARCH("Foreign",Table2[[#This Row],[Emp_Name]])),"Remote",""))) -> Hybrid | Z16: 20 | AA16: =IF(OR(Table2[[#This Row],[Role]]="Intern",Table2[[#This Row],[Role]]="Administrative Assistant",Table2[[#This Row],[Role]]="Analyst"), Table2[[#This Row],[Overtime_Hours]]*250, IF(OR(Table2[[#This Row],[Role]]="Senior Analyst",Table2[[#This Row],[Role]]="Specialist",Table2[[#This Row],[Role]]="Lead Analyst"), Table2[[#This Row],[Overtime_Hours]]*300, IF(OR(Table2[[#This Row],[Role]]="Manager",Table2[[#This Row],[Role]]="Senior Manager"), Table2[[#This Row],[Overtime_Hours]]*350, ""))) -> 6000 | AB16: High | AC16: =IF(COUNTIF(Table2[Emp_ID],Table2[[#This Row],[Emp_ID]])>1,"Duplicate","Unique") -> Unique | AD16: =_xlfn.TEXTJOIN("|",TRUE,Table2[[#This Row],[Emp_ID]:[Salary_Band]]) -> ZOM1451|Employee_451_India|26|Gurugram|Analytics|Senior Analyst|INR|INR|48000|12|12|576000|4|4|4|15000|14400|90|15|1|Yes|Hybrid|Hybrid|20|6000|High | AE16: =IF(COUNTIFS(Table2[Emp_ID],Table2[[#This Row],[Emp_ID]],Table2[Row_Concat],Table2[[#This Row],[Row_Concat]])>1,"Exact Duplicate", IF(COUNTIF(Table2[Emp_ID],Table2[[#This Row],[Emp_ID]])>1,"Mismatch","Unique")) -> Unique | AF16: =ROW() -> 16 | AG16: =IF(Table2[[#This Row],[Monthly_Salary]]="","Exclude", IF(Table2[[#This Row],[Row_Status]]="Mismatch","Exclude", IF(AND(Table2[[#This Row],[Row_Status]]="Exact Duplicate", COUNTIFS(Table2[Emp_ID],Table2[[#This Row],[Emp_ID]],Table2[Row_Concat],Table2[[#This Row],[Row_Concat]], Table2[Row_Number],"<"&Table2[[#This Row],[Row_Number]])>=1),"Delete",""))) | AH16: =VLOOKUP(Table2[[#This Row],[Department]],Raw_2!A:B,2,0) -> Day | AI16: =VLOOKUP(Table2[[#This Row],[Department]],Raw_2!A:C,3,0) -> 25
A17: ZOM1206 | B17: Employee_206_India | C17: 45 | D17: Female | E17: =IF(OR(Table2[[#This Row],[Gender]]="Male",Table2[[#This Row],[Gender]]="M"),"M", IF(OR(Table2[[#This Row],[Gender]]="Female",Table2[[#This Row],[Gender]]="F"),"F","")) -> F | F17: Bangalore | G17: Analytics | H17: Director | I17: USD | J17: =IF(ISNUMBER(SEARCH("India",Table2[[#This Row],[Emp_Name]])),"INR", IF(ISNUMBER(SEARCH("Foreign",Table2[[#This Row],[Emp_Name]])),Table2[[#This Row],[Currency]],Table2[[#This Row],[Currency]])) -> INR | K17: 110000 | L17: 12 | M17: =IF(Table2[[#This Row],[Num_Month]]<>12,12,Table2[[#This Row],[Num_Month]]) -> 12 | N17: =IF(Table2[[#This Row],[Monthly_Salary]]="","",Table2[[#This Row],[Monthly_Salary]]*Table2[[#This Row],[Num_Month_Final]]) -> 1320000 | O17: 10 | P17: =IF(Table2[[#This Row],[Exp_Years]]<0,ABS(Table2[[#This Row],[Exp_Years]]),Table2[[#This Row],[Exp_Years]]) -> 10 | Q17: 2 | S17: =IF(Table2[[#This Row],[Performance_Rating]]>=3,Table2[[#This Row],[Monthly_Salary]]*0.3,"") | T17: 88 | U17: 7 | V17: 5 | W17: Yes | X17: Office | Y17: =IF(Table2[[#This Row],[Work_Mode]]<>"",Table2[[#This Row],[Work_Mode]], IF(ISNUMBER(SEARCH("India",Table2[[#This Row],[Emp_Name]])),"Office", IF(ISNUMBER(SEARCH("Foreign",Table2[[#This Row],[Emp_Name]])),"Remote",""))) -> Office | AA17: =IF(OR(Table2[[#This Row],[Role]]="Intern",Table2[[#This Row],[Role]]="Administrative Assistant",Table2[[#This Row],[Role]]="Analyst"), Table2[[#This Row],[Overtime_Hours]]*250, IF(OR(Table2[[#This Row],[Role]]="Senior Analyst",Table2[[#This Row],[Role]]="Specialist",Table2[[#This Row],[Role]]="Lead Analyst"), Table2[[#This Row],[Overtime_Hours]]*300, IF(OR(Table2[[#This Row],[Role]]="Manager",Table2[[#This Row],[Role]]="Senior Manager"), Table2[[#This Row],[Overtime_Hours]]*350, ""))) | AB17: Low | AC17: =IF(COUNTIF(Table2[Emp_ID],Table2[[#This Row],[Emp_ID]])>1,"Duplicate","Unique") -> Unique | AD17: =_xlfn.TEXTJOIN("|",TRUE,Table2[[#This Row],[Emp_ID]:[Salary_Band]]) -> ZOM1206|Employee_206_India|45|Female|F|Bangalore|Analytics|Director|USD|INR|110000|12|12|1320000|10|10|2|88|7|5|Yes|Office|Office|Low | AE17: =IF(COUNTIFS(Table2[Emp_ID],Table2[[#This Row],[Emp_ID]],Table2[Row_Concat],Table2[[#This Row],[Row_Concat]])>1,"Exact Duplicate", IF(COUNTIF(Table2[Emp_ID],Table2[[#This Row],[Emp_ID]])>1,"Mismatch","Unique")) -> Unique | AF17: =ROW() -> 17 | AG17: =IF(Table2[[#This Row],[Monthly_Salary]]="","Exclude", IF(Table2[[#This Row],[Row_Status]]="Mismatch","Exclude", IF(AND(Table2[[#This Row],[Row_Status]]="Exact Duplicate", COUNTIFS(Table2[Emp_ID],Table2[[#This Row],[Emp_ID]],Table2[Row_Concat],Table2[[#This Row],[Row_Concat]], Table2[Row_Number],"<"&Table2[[#This Row],[Row_Number]])>=1),"Delete",""))) | AH17: =VLOOKUP(Table2[[#This Row],[Department]],Raw_2!A:B,2,0) -> Day | AI17: =VLOOKUP(Table2[[#This Row],[Department]],Raw_2!A:C,3,0) -> 25
